{"trial_id": "07", "hyperparameters": {"space": [{"class_name": "Choice", "config": {"name": "num_lstm_units_first_layer", "default": 32, "conditions": [], "values": [32, 64, 128, 256], "ordered": true}}, {"class_name": "Int", "config": {"name": "num_lstm_layers", "default": null, "conditions": [], "min_value": 1, "max_value": 3, "step": 1, "sampling": "linear"}}, {"class_name": "Float", "config": {"name": "dropout_rate", "default": 0.0, "conditions": [], "min_value": 0.0, "max_value": 0.3, "step": 0.1, "sampling": "linear"}}, {"class_name": "Choice", "config": {"name": "num_lstm_units_layer_2", "default": 32, "conditions": [], "values": [32, 64, 128, 256], "ordered": true}}, {"class_name": "Choice", "config": {"name": "num_lstm_units_layer_3", "default": 32, "conditions": [], "values": [32, 64, 128, 256], "ordered": true}}], "values": {"num_lstm_units_first_layer": 64, "num_lstm_layers": 3, "dropout_rate": 0.1, "num_lstm_units_layer_2": 256, "num_lstm_units_layer_3": 128}}, "metrics": {"metrics": {}}, "score": null, "best_step": 0, "status": "FAILED", "message": "Traceback (most recent call last):\n  File \"c:\\Users\\elian\\anaconda3\\envs\\tensorflow-cpu\\lib\\site-packages\\keras_tuner\\src\\engine\\base_tuner.py\", line 274, in _try_run_and_update_trial\n    self._run_and_update_trial(trial, *fit_args, **fit_kwargs)\n  File \"c:\\Users\\elian\\anaconda3\\envs\\tensorflow-cpu\\lib\\site-packages\\keras_tuner\\src\\engine\\base_tuner.py\", line 239, in _run_and_update_trial\n    results = self.run_trial(trial, *fit_args, **fit_kwargs)\n  File \"c:\\Users\\elian\\anaconda3\\envs\\tensorflow-cpu\\lib\\site-packages\\keras_tuner\\src\\engine\\tuner.py\", line 314, in run_trial\n    obj_value = self._build_and_fit_model(trial, *args, **copied_kwargs)\n  File \"c:\\Users\\elian\\anaconda3\\envs\\tensorflow-cpu\\lib\\site-packages\\keras_tuner\\src\\engine\\tuner.py\", line 232, in _build_and_fit_model\n    model = self._try_build(hp)\n  File \"c:\\Users\\elian\\anaconda3\\envs\\tensorflow-cpu\\lib\\site-packages\\keras_tuner\\src\\engine\\tuner.py\", line 164, in _try_build\n    model = self._build_hypermodel(hp)\n  File \"c:\\Users\\elian\\anaconda3\\envs\\tensorflow-cpu\\lib\\site-packages\\keras_tuner\\src\\engine\\tuner.py\", line 155, in _build_hypermodel\n    model = self.hypermodel.build(hp)\n  File \"C:\\Users\\elian\\AppData\\Local\\Temp\\ipykernel_63440\\3268805284.py\", line 17, in build_model\n    model.add(LSTM(hp.Choice(f'num_lstm_units_layer_{i+2}', values=[32, 64, 128, 256])))\n  File \"c:\\Users\\elian\\anaconda3\\envs\\tensorflow-cpu\\lib\\site-packages\\tensorflow\\python\\trackable\\base.py\", line 205, in _method_wrapper\n    result = method(self, *args, **kwargs)\n  File \"c:\\Users\\elian\\anaconda3\\envs\\tensorflow-cpu\\lib\\site-packages\\keras\\utils\\traceback_utils.py\", line 70, in error_handler\n    raise e.with_traceback(filtered_tb) from None\n  File \"c:\\Users\\elian\\anaconda3\\envs\\tensorflow-cpu\\lib\\site-packages\\keras\\engine\\input_spec.py\", line 232, in assert_input_compatibility\n    raise ValueError(\nValueError: Input 0 of layer \"lstm_2\" is incompatible with the layer: expected ndim=3, found ndim=2. Full shape received: (None, 256)\n"}