{"trial_id": "00", "hyperparameters": {"space": [{"class_name": "Int", "config": {"name": "units_l1", "default": null, "conditions": [], "min_value": 64, "max_value": 256, "step": 64, "sampling": "linear"}}, {"class_name": "Choice", "config": {"name": "return_seq", "default": 1, "conditions": [], "values": [1, 0], "ordered": true}}, {"class_name": "Int", "config": {"name": "num_layers", "default": null, "conditions": [], "min_value": 1, "max_value": 3, "step": 1, "sampling": "linear"}}, {"class_name": "Int", "config": {"name": "units_l2", "default": null, "conditions": [], "min_value": 64, "max_value": 256, "step": 64, "sampling": "linear"}}, {"class_name": "Float", "config": {"name": "dropout", "default": 0.0, "conditions": [], "min_value": 0.0, "max_value": 0.3, "step": 0.1, "sampling": "linear"}}, {"class_name": "Choice", "config": {"name": "learning_rate", "default": 0.01, "conditions": [], "values": [0.01, 0.001, 0.0001], "ordered": true}}], "values": {"units_l1": 256, "return_seq": 0, "num_layers": 2, "units_l2": 64, "dropout": 0.1, "learning_rate": 0.001}}, "metrics": {"metrics": {}}, "score": null, "best_step": 0, "status": "FAILED", "message": "Traceback (most recent call last):\n  File \"c:\\Users\\elian\\anaconda3\\envs\\tensorflow-cpu\\lib\\site-packages\\keras_tuner\\src\\engine\\base_tuner.py\", line 274, in _try_run_and_update_trial\n    self._run_and_update_trial(trial, *fit_args, **fit_kwargs)\n  File \"c:\\Users\\elian\\anaconda3\\envs\\tensorflow-cpu\\lib\\site-packages\\keras_tuner\\src\\engine\\base_tuner.py\", line 239, in _run_and_update_trial\n    results = self.run_trial(trial, *fit_args, **fit_kwargs)\n  File \"c:\\Users\\elian\\anaconda3\\envs\\tensorflow-cpu\\lib\\site-packages\\keras_tuner\\src\\engine\\tuner.py\", line 314, in run_trial\n    obj_value = self._build_and_fit_model(trial, *args, **copied_kwargs)\n  File \"c:\\Users\\elian\\anaconda3\\envs\\tensorflow-cpu\\lib\\site-packages\\keras_tuner\\src\\engine\\tuner.py\", line 232, in _build_and_fit_model\n    model = self._try_build(hp)\n  File \"c:\\Users\\elian\\anaconda3\\envs\\tensorflow-cpu\\lib\\site-packages\\keras_tuner\\src\\engine\\tuner.py\", line 164, in _try_build\n    model = self._build_hypermodel(hp)\n  File \"c:\\Users\\elian\\anaconda3\\envs\\tensorflow-cpu\\lib\\site-packages\\keras_tuner\\src\\engine\\tuner.py\", line 155, in _build_hypermodel\n    model = self.hypermodel.build(hp)\n  File \"C:\\Users\\elian\\AppData\\Local\\Temp\\ipykernel_99556\\1580144715.py\", line 10, in build_model\n    model.add(LSTM(hp.Int(f'units_l{i+2}', min_value=64, max_value=256, step=64), return_sequences=False if i==hp.get('num_layers')-1 else True))\n  File \"c:\\Users\\elian\\anaconda3\\envs\\tensorflow-cpu\\lib\\site-packages\\tensorflow\\python\\trackable\\base.py\", line 205, in _method_wrapper\n    result = method(self, *args, **kwargs)\n  File \"c:\\Users\\elian\\anaconda3\\envs\\tensorflow-cpu\\lib\\site-packages\\keras\\utils\\traceback_utils.py\", line 70, in error_handler\n    raise e.with_traceback(filtered_tb) from None\n  File \"c:\\Users\\elian\\anaconda3\\envs\\tensorflow-cpu\\lib\\site-packages\\keras\\engine\\input_spec.py\", line 232, in assert_input_compatibility\n    raise ValueError(\nValueError: Input 0 of layer \"lstm_1\" is incompatible with the layer: expected ndim=3, found ndim=2. Full shape received: (None, 256)\n"}