{"trial_id": "03", "hyperparameters": {"space": [{"class_name": "Int", "config": {"name": "units_l1", "default": null, "conditions": [], "min_value": 64, "max_value": 256, "step": 64, "sampling": "linear"}}, {"class_name": "Choice", "config": {"name": "return_seq", "default": 1, "conditions": [], "values": [1, 0], "ordered": true}}, {"class_name": "Int", "config": {"name": "num_layers", "default": null, "conditions": [], "min_value": 1, "max_value": 3, "step": 1, "sampling": "linear"}}, {"class_name": "Int", "config": {"name": "units_l2", "default": null, "conditions": [], "min_value": 64, "max_value": 256, "step": 64, "sampling": "linear"}}, {"class_name": "Float", "config": {"name": "dropout", "default": 0.0, "conditions": [], "min_value": 0.0, "max_value": 0.3, "step": 0.1, "sampling": "linear"}}, {"class_name": "Choice", "config": {"name": "learning_rate", "default": 0.01, "conditions": [], "values": [0.01, 0.001, 0.0001], "ordered": true}}, {"class_name": "Int", "config": {"name": "units_l3", "default": null, "conditions": [], "min_value": 64, "max_value": 256, "step": 64, "sampling": "linear"}}], "values": {"units_l1": 64, "return_seq": 1, "num_layers": 1, "units_l2": 128, "dropout": 0.1, "learning_rate": 0.0001, "units_l3": 64}}, "metrics": {"metrics": {}}, "score": null, "best_step": 0, "status": "FAILED", "message": "Traceback (most recent call last):\n  File \"c:\\Users\\elian\\anaconda3\\envs\\tensorflow-cpu\\lib\\site-packages\\keras_tuner\\src\\engine\\base_tuner.py\", line 274, in _try_run_and_update_trial\n    self._run_and_update_trial(trial, *fit_args, **fit_kwargs)\n  File \"c:\\Users\\elian\\anaconda3\\envs\\tensorflow-cpu\\lib\\site-packages\\keras_tuner\\src\\engine\\base_tuner.py\", line 239, in _run_and_update_trial\n    results = self.run_trial(trial, *fit_args, **fit_kwargs)\n  File \"c:\\Users\\elian\\anaconda3\\envs\\tensorflow-cpu\\lib\\site-packages\\keras_tuner\\src\\engine\\tuner.py\", line 314, in run_trial\n    obj_value = self._build_and_fit_model(trial, *args, **copied_kwargs)\n  File \"c:\\Users\\elian\\anaconda3\\envs\\tensorflow-cpu\\lib\\site-packages\\keras_tuner\\src\\engine\\tuner.py\", line 233, in _build_and_fit_model\n    results = self.hypermodel.fit(hp, model, *args, **kwargs)\n  File \"c:\\Users\\elian\\anaconda3\\envs\\tensorflow-cpu\\lib\\site-packages\\keras_tuner\\src\\engine\\hypermodel.py\", line 149, in fit\n    return model.fit(*args, **kwargs)\n  File \"c:\\Users\\elian\\anaconda3\\envs\\tensorflow-cpu\\lib\\site-packages\\keras\\utils\\traceback_utils.py\", line 70, in error_handler\n    raise e.with_traceback(filtered_tb) from None\n  File \"c:\\Users\\elian\\anaconda3\\envs\\tensorflow-cpu\\lib\\site-packages\\tensorflow\\python\\eager\\execute.py\", line 54, in quick_execute\n    tensors = pywrap_tfe.TFE_Py_Execute(ctx._handle, device_name, op_name,\ntensorflow.python.framework.errors_impl.InvalidArgumentError: Graph execution error:\n\nDetected at node 'sub' defined at (most recent call last):\n    File \"c:\\Users\\elian\\anaconda3\\envs\\tensorflow-cpu\\lib\\runpy.py\", line 194, in _run_module_as_main\n      return _run_code(code, main_globals, None,\n    File \"c:\\Users\\elian\\anaconda3\\envs\\tensorflow-cpu\\lib\\runpy.py\", line 87, in _run_code\n      exec(code, run_globals)\n    File \"c:\\Users\\elian\\anaconda3\\envs\\tensorflow-cpu\\lib\\site-packages\\ipykernel_launcher.py\", line 18, in <module>\n      app.launch_new_instance()\n    File \"c:\\Users\\elian\\anaconda3\\envs\\tensorflow-cpu\\lib\\site-packages\\traitlets\\config\\application.py\", line 1075, in launch_instance\n      app.start()\n    File \"c:\\Users\\elian\\anaconda3\\envs\\tensorflow-cpu\\lib\\site-packages\\ipykernel\\kernelapp.py\", line 739, in start\n      self.io_loop.start()\n    File \"c:\\Users\\elian\\anaconda3\\envs\\tensorflow-cpu\\lib\\site-packages\\tornado\\platform\\asyncio.py\", line 215, in start\n      self.asyncio_loop.run_forever()\n    File \"c:\\Users\\elian\\anaconda3\\envs\\tensorflow-cpu\\lib\\asyncio\\base_events.py\", line 570, in run_forever\n      self._run_once()\n    File \"c:\\Users\\elian\\anaconda3\\envs\\tensorflow-cpu\\lib\\asyncio\\base_events.py\", line 1859, in _run_once\n      handle._run()\n    File \"c:\\Users\\elian\\anaconda3\\envs\\tensorflow-cpu\\lib\\asyncio\\events.py\", line 81, in _run\n      self._context.run(self._callback, *self._args)\n    File \"c:\\Users\\elian\\anaconda3\\envs\\tensorflow-cpu\\lib\\site-packages\\ipykernel\\kernelbase.py\", line 545, in dispatch_queue\n      await self.process_one()\n    File \"c:\\Users\\elian\\anaconda3\\envs\\tensorflow-cpu\\lib\\site-packages\\ipykernel\\kernelbase.py\", line 534, in process_one\n      await dispatch(*args)\n    File \"c:\\Users\\elian\\anaconda3\\envs\\tensorflow-cpu\\lib\\site-packages\\ipykernel\\kernelbase.py\", line 437, in dispatch_shell\n      await result\n    File \"c:\\Users\\elian\\anaconda3\\envs\\tensorflow-cpu\\lib\\site-packages\\ipykernel\\ipkernel.py\", line 359, in execute_request\n      await super().execute_request(stream, ident, parent)\n    File \"c:\\Users\\elian\\anaconda3\\envs\\tensorflow-cpu\\lib\\site-packages\\ipykernel\\kernelbase.py\", line 778, in execute_request\n      reply_content = await reply_content\n    File \"c:\\Users\\elian\\anaconda3\\envs\\tensorflow-cpu\\lib\\site-packages\\ipykernel\\ipkernel.py\", line 446, in do_execute\n      res = shell.run_cell(\n    File \"c:\\Users\\elian\\anaconda3\\envs\\tensorflow-cpu\\lib\\site-packages\\ipykernel\\zmqshell.py\", line 549, in run_cell\n      return super().run_cell(*args, **kwargs)\n    File \"c:\\Users\\elian\\anaconda3\\envs\\tensorflow-cpu\\lib\\site-packages\\IPython\\core\\interactiveshell.py\", line 3006, in run_cell\n      result = self._run_cell(\n    File \"c:\\Users\\elian\\anaconda3\\envs\\tensorflow-cpu\\lib\\site-packages\\IPython\\core\\interactiveshell.py\", line 3061, in _run_cell\n      result = runner(coro)\n    File \"c:\\Users\\elian\\anaconda3\\envs\\tensorflow-cpu\\lib\\site-packages\\IPython\\core\\async_helpers.py\", line 129, in _pseudo_sync_runner\n      coro.send(None)\n    File \"c:\\Users\\elian\\anaconda3\\envs\\tensorflow-cpu\\lib\\site-packages\\IPython\\core\\interactiveshell.py\", line 3266, in run_cell_async\n      has_raised = await self.run_ast_nodes(code_ast.body, cell_name,\n    File \"c:\\Users\\elian\\anaconda3\\envs\\tensorflow-cpu\\lib\\site-packages\\IPython\\core\\interactiveshell.py\", line 3445, in run_ast_nodes\n      if await self.run_code(code, result, async_=asy):\n    File \"c:\\Users\\elian\\anaconda3\\envs\\tensorflow-cpu\\lib\\site-packages\\IPython\\core\\interactiveshell.py\", line 3505, in run_code\n      exec(code_obj, self.user_global_ns, self.user_ns)\n    File \"C:\\Users\\elian\\AppData\\Local\\Temp\\ipykernel_99556\\3453908190.py\", line 2, in <module>\n      tuner.search(X_train, y_train,\n    File \"c:\\Users\\elian\\anaconda3\\envs\\tensorflow-cpu\\lib\\site-packages\\keras_tuner\\src\\engine\\base_tuner.py\", line 234, in search\n      self._try_run_and_update_trial(trial, *fit_args, **fit_kwargs)\n    File \"c:\\Users\\elian\\anaconda3\\envs\\tensorflow-cpu\\lib\\site-packages\\keras_tuner\\src\\engine\\base_tuner.py\", line 274, in _try_run_and_update_trial\n      self._run_and_update_trial(trial, *fit_args, **fit_kwargs)\n    File \"c:\\Users\\elian\\anaconda3\\envs\\tensorflow-cpu\\lib\\site-packages\\keras_tuner\\src\\engine\\base_tuner.py\", line 239, in _run_and_update_trial\n      results = self.run_trial(trial, *fit_args, **fit_kwargs)\n    File \"c:\\Users\\elian\\anaconda3\\envs\\tensorflow-cpu\\lib\\site-packages\\keras_tuner\\src\\engine\\tuner.py\", line 314, in run_trial\n      obj_value = self._build_and_fit_model(trial, *args, **copied_kwargs)\n    File \"c:\\Users\\elian\\anaconda3\\envs\\tensorflow-cpu\\lib\\site-packages\\keras_tuner\\src\\engine\\tuner.py\", line 233, in _build_and_fit_model\n      results = self.hypermodel.fit(hp, model, *args, **kwargs)\n    File \"c:\\Users\\elian\\anaconda3\\envs\\tensorflow-cpu\\lib\\site-packages\\keras_tuner\\src\\engine\\hypermodel.py\", line 149, in fit\n      return model.fit(*args, **kwargs)\n    File \"c:\\Users\\elian\\anaconda3\\envs\\tensorflow-cpu\\lib\\site-packages\\keras\\utils\\traceback_utils.py\", line 65, in error_handler\n      return fn(*args, **kwargs)\n    File \"c:\\Users\\elian\\anaconda3\\envs\\tensorflow-cpu\\lib\\site-packages\\keras\\engine\\training.py\", line 1564, in fit\n      tmp_logs = self.train_function(iterator)\n    File \"c:\\Users\\elian\\anaconda3\\envs\\tensorflow-cpu\\lib\\site-packages\\keras\\engine\\training.py\", line 1160, in train_function\n      return step_function(self, iterator)\n    File \"c:\\Users\\elian\\anaconda3\\envs\\tensorflow-cpu\\lib\\site-packages\\keras\\engine\\training.py\", line 1146, in step_function\n      outputs = model.distribute_strategy.run(run_step, args=(data,))\n    File \"c:\\Users\\elian\\anaconda3\\envs\\tensorflow-cpu\\lib\\site-packages\\keras\\engine\\training.py\", line 1135, in run_step\n      outputs = model.train_step(data)\n    File \"c:\\Users\\elian\\anaconda3\\envs\\tensorflow-cpu\\lib\\site-packages\\keras\\engine\\training.py\", line 998, in train_step\n      return self.compute_metrics(x, y, y_pred, sample_weight)\n    File \"c:\\Users\\elian\\anaconda3\\envs\\tensorflow-cpu\\lib\\site-packages\\keras\\engine\\training.py\", line 1092, in compute_metrics\n      self.compiled_metrics.update_state(y, y_pred, sample_weight)\n    File \"c:\\Users\\elian\\anaconda3\\envs\\tensorflow-cpu\\lib\\site-packages\\keras\\engine\\compile_utils.py\", line 605, in update_state\n      metric_obj.update_state(y_t, y_p, sample_weight=mask)\n    File \"c:\\Users\\elian\\anaconda3\\envs\\tensorflow-cpu\\lib\\site-packages\\keras\\utils\\metrics_utils.py\", line 77, in decorated\n      update_op = update_state_fn(*args, **kwargs)\n    File \"c:\\Users\\elian\\anaconda3\\envs\\tensorflow-cpu\\lib\\site-packages\\keras\\metrics\\base_metric.py\", line 143, in update_state_fn\n      return ag_update_state(*args, **kwargs)\n    File \"c:\\Users\\elian\\anaconda3\\envs\\tensorflow-cpu\\lib\\site-packages\\keras\\metrics\\base_metric.py\", line 700, in update_state\n      matches = ag_fn(y_true, y_pred, **self._fn_kwargs)\n    File \"c:\\Users\\elian\\anaconda3\\envs\\tensorflow-cpu\\lib\\site-packages\\keras\\losses.py\", line 1627, in mean_absolute_error\n      return backend.mean(tf.abs(y_pred - y_true), axis=-1)\nNode: 'sub'\nIncompatible shapes: [16,144,72] vs. [16,72]\n\t [[{{node sub}}]] [Op:__inference_train_function_68359]\n"}